Workbook

Sheet Jan_2024_FinancialReport
D2: OUR LADY OF THE MOST HOLY ROSARY
D3: Sub-Parish
D4: Diamond Crest Village
D5: Bgy. San Manuel, City of San Jose del Monte
G8: FINANCIAL REPORT
G9: January 2024
B12: Beginning balance as of January 01, 2024\\ | O12: 12090
I13: Less : Add'l | K13: Net
B14: Mass Collections for: | G14: Sunday | I14: Stipend | K14: Amount
D15: January | F15: 01 | G15: 1276 | I15: 0 | K15: 1276
F16: 07 | G16: (no mass)
F17: 14 | G17: 1860 | K17: 1860
F18: 21 | G18: 2590 | I18: 1000 | K18: 1590
F19: 28 | G19: 2376 | I19: 1000 | K19: 1376
D20: Sub-total | G20: =SUM(G15:G19) -> 8102 | I20: 2000 | K20: =SUM(K14:K19) -> 6102 | M20: 6102
B21: Add: Donations/Thanksgiving:
B22: Date | F22: Donor | I22: Rcpt. # | K22: Amount
F23: Donations / Pamisa | K23: 2200
B25: TOTAL COLLECTION FOR January …………… | O25: 8302
B27: TOTAL CASH AVAILABLE ……………. | O27: =SUM(O12:O25) -> 20392
B29: Less: | D29: Expenses for January:
B30: Date | D30: PCV # | G30: P A R T I C U L A R S | M30: Amount
B31: 01/04/24 | F31: Desk Fan repair | M31: 300
B32: 01/10/24 | F32: Wire screen for back door | M32: 540
B33: 01/13/24 | F33: Michael - labor: removed x'mas lights | M33: 500
B34: 01/18/24 | F34: Office supplies | M34: 122
B35: 01/16/24 | F35: Meralco/Water Bills (2 mos.) | M35: 2457.45
B36: 01/21/24 | F36: SLRP Anniversary | M36: 3500
B37: TOTAL EXPENSES FOR JANUARY ……………………………………… | O37: =SUM(M31:M36) -> 7419.45
D39: Cash Balance as of January 31, 2024 …………………… | O39: 12972.55
D41: Cash in Bank as of December 31, 2024 | M41: 47848.34
D42: Add: | F42: Interest (net of w/holding tax) | M42: 4.12
D43: Cash in Bank as of January 31, 2024 | M43: =SUM(M41:M42) -> 47852.46
B46: Prepared by | F46: Checked by | I46: Audited by: | M46: Noted by:
F49: Fely Rabano | I49: Tina Murla | M49: Lucky Tiu
B50: Asst. Treasurer | F50: Treasurer | I50: Auditor | M50: President

Sheet Jan. 2024_AckReceipt
G2: Our Lady of the Most Holy Rosary (Sub-Parish)
A3: Control File - Receipts
A4: Month of January 2024
G6: Pamisa & | L6: from mass | M6: Total
A7: Date | D7: Rcpt. # | F7: Donor | G7: Thanksgiving | I7: Donation | J7: Stipend | L7: collection | M7: Stipend | N7: Date
A8: Jan.
A9: 01 | D9: 2563 | F9: F. Rabano | G9: 100
A10: 01 | D10: 2564 | F10: Jane Pasamba | G10: 100
A11: 01 | D11: 2565 | F11: Elmer Buere | G11: 100
A12: 01 | D12: 2566 | F12: Leony Aviles | G12: 200
A13: 01 | D13: 2567 | F13: Beng Grafil | G13: 300
A14: 01 | D14: 2568 | F14: Tina Murla | G14: 500 | J14: =SUM(G9:G14) -> 1300 | L14: 200 | M14: 1500 | N14: Jan. 04
A15: 14 | D15: 2569 | F15: Imelda | G15: 100
A16: 14 | D16: 2570 | F16: Gina Albarido | G16: 100
A17: 14 | D17: 2572 | F17: Lucy Saramosing | G17: 100
A18: 14 | D18: 2573 | F18: Jane Pasamba | G18: 100
A19: 14 | D19: 2574 | F19: Art de Leon | G19: 500
A20: 14 | D20: 2575 | F20: Elmer Buere | G20: 100
A21: 14 | D21: 2576 | F21: Leo Grafil | G21: 100
A22: 14 | D22: 2577 | F22: Nida Alberto | G22: 1000
A23: 14 | D23: 2578 | F23: Baby Boris | G23: 100 | I23: 1100 | M23: 1000 | N23: Jan. 15
A24: 21 | D24: 2579 | F24: Thin Tapaon | G24: 100 | I24: 100 | L24: 1000 | M24: 1000 | N24: Jan. 21
A25: 28 | D25: 2571 | F25: Art de Leon | G25: 200
A26: 28 | D26: 2580 | F26: Gina Albarido | G26: 100
A27: 28 | D27: 2581 | F27: Art de Leon | G27: 200
A28: 28 | D28: 2582 | F28: Perla | G28: 100
A29: 28 | D29: 2583 | F29: Nanie Domingo | G29: 100
A30: 28 | D30: 2584 | F30: Elmer Buere | G30: 100
A31: 28 | D31: 2585 | F31: Susan | G31: 100
A32: 28 | D32: 2586 | F32: Thin Tapaon | G32: 100 | I32: =SUM(G25:G32) -> 1000 | L32: 1000 | M32: 1000 | N32: Jan. 28
I33: =SUM(I22:I32) -> 2200
D35: Prepared by:
A38: Date | J38: Stipend
A39: January | D39: 01 | F39: (New Year) | J39: 1500
D40: 07 | F40: No Mass)
D41: 14 | J41: 1000
D42: 21 | J42: 1000
D43: 28 | J43: 1000
J44: 4500

Sheet FEB_2024_Sched A
B2: Schedule A
B7: Our Lady of the Most Holy Rosary (Sub-Parish)
G8: Control File - Receipts
F9: For the month of February 2024
G11: DONATIONS (Mass Intentions:Thanksgiving, Souls, others) | H11: DONATIONS | I11: Net of Donations | J11: STIPEND from | L11: Total Stipend
B12: Date | D12: OR Number | F12: Donor | J12: Donations | K12: Mass Collections
B13: February
B14: 04 | D14: 2587 | F14: Art de Leon | G14: 100
B15: 04 | D15: 2588 | F15: Elmer Buere | G15: 100
B16: 04 | D16: 2589 | F16: Annie | G16: 20
B17: 04 | F17: No Offical Receipt | G17: 80
B18: Sub-Total | G18: =SUM(G14:G17) -> 300 | I18: =G18-J18 -> 0 | J18: 300 | K18: 700 | L18: =J18+K18 -> 1000
B19: 11 | D19: 2590 | F19: Fely Rabano | G19: 100
B20: 11 | D20: 2591 | F20: Gina Albarido | G20: 100
B21: 11 | D21: 2592 | F21: Jane P. | G21: 100
B22: 11 | D22: 2593 | F22: Imelda | G22: 100
B23: Sub-Total | G23: =SUM(G19:G22) -> 400 | I23: =G23-J23 -> 0 | J23: 400 | K23: 600 | L23: =J23+K23 -> 1000
B24: 18 | D24: 2594 | F24: Annie | G24: 50
B25: 18 | D25: 2595 | F25: Art de Leon | G25: 200
B26: 18 | D26: 2596 | F26: Elmer Buere | G26: 100
B27: 18 | D27: 2597 | F27: Hilda | G27: 200
B28: 18 | D28: 2598 | F28: Irene Masong | G28: 100
B29: 18 | D29: 2599 | F29: Aviles Family | G29: 150
B30: 18 | D30: 2600 | F30: Beng Grafil | G30: 100
B31: Sub-Total | G31: =SUM(G24:G30) -> 900 | I31: =G31-J31 -> 0 | J31: 900 | K31: 100 | L31: =J31+K31 -> 1000
B32: 25 | D32: 2601 | F32: Lourdes Galang | G32: 50
B33: 25 | D33: 2602 | F33: Annie | G33: 20
B34: 25 | D34: 2603 | F34: Art de Leon | G34: 200
B35: 25 | D35: 2604 | F35: Jane P. | G35: 100
B36: 25 | D36: 2605 | F36: Unused OR | G36: 0
B37: 25 | D37: 2606 | F37: Aviles Family | G37: 150
B38: Sub-Total | G38: =SUM(G32:G37) -> 520 | I38: =G38-J38 -> 50 | J38: 470 | K38: 530 | L38: =J38+K38 -> 1000
B39: TOTAL | G39: =G38+G31+G23+G18 -> 2120 | I39: =I38+I31+I23+I18 -> 50 | J39: =J38+J31+J23+J18 -> 2070 | K39: =K38+K31+K23+K18 -> 1930 | L39: =L38+L31+L23+L18 -> 4000
B48: Stipend for the month of February 2024
B50: Period covered | F50: Amount
B51: February | C51: 04 | F51: 1000
B52: February | C52: 11 | F52: 1000
B53: February | C53: 18 | F53: 1000
B54: February | C54: 25 | F54: 1000
B56: Total Stipend | F56: =SUM(F51:F54) -> 4000

Sheet FEB_2024_FR
C4: Our Lady of the Most Holy Rosary (Sub-Parish)
C5: Diamond Crest Village ,Brgy, San Manuel, San Jose DelMonte City, Bulacan
C7: FINANCIAL REPORT
C8: As of FEBRUARY 29, 2024
C10: Cash Balance as of February 01, 2024 | K10: P | L10: 12972.55
C12: Add: Receipts for the month of February
C14: Mass Collections: | G14: (Net of Stipend)
H16: Collections | I16: Stipend | J16: Net Amount
E18: February | G18: 04 | H18: =881 -> 881 | I18: 700 | J18: =H18-I18 -> 181
E19: February | G19: 11 | H19: 2340 | I19: 600 | J19: =H19-I19 -> 1740
E20: February | G20: 18 | H20: 1807 | I20: 100 | J20: =H20-I20 -> 1707
E21: February | G21: 25 | H21: 2225 | I21: 530 | J21: =H21-I21 -> 1695
E23: Total | H23: =SUM(H18:H21) -> 7253 | I23: =SUM(I18:I21) -> 1930 | J23: =SUM(J18:J21) -> 5323
C26: Donations from Mass Intentions : ( Schedule A)
E28: Donations (Net of Stipend) | J28: 50 | L28: =J23+J28 -> 5373 | N28: =L28-3915 -> 1458
C30: Total Cash Available | K30: P | L30: =L28+L10 -> 18345.55
C32: Less: Expenses for the month of February
C34: Date | E34: PCV # | G34: P articulars | J34: Amount
C36: 45506 | G36: Utility Expenses (Meralco/Water Bills ) | J36: 1206.8
C37: 45567 | G37: Electrical/Labor expenses -(c/o Jaime ) | J37: =575 -> 575
C38: 45598 | G38: SPPC Share for Annual Planning | J38: 1000
C39: 02/16/2024 | G39: Food Expenses ( Daan ng Krus ) | J39: 1134.5
C40: 02/22/2024 | G40: Repairs of cabinet | J40: 200 | L40: =SUM(J36:J40) -> 4116.3
C42: Net of Expenses | L42: =L30-L40 -> 14229.25
C44: Less: Deposits for the month of February | L44: 12090
C46: Cash Balance as of February 29, 2024 | K46: P | L46: =L42-L44 -> 2139.25
C50: Cash in Bank as of January 31, 2024 | K50: P | L50: 47852.46
C52: Add: Deposits - February 2024 | L52: 12090
C53: Interest ( Net of witholding tax ) | L53: =5.75-1.15 -> 4.6
C54: Cash in Bank as of February 29, 2024 | K54: P | L54: =SUM(L50:L53) -> 59947.06
C59: Prepared by: | G59: Checked by: | I59: Audited by: | L59: Noted by:
C61: Elvira Grafil | G61: Fely Rabano | I61: Tina Murla | L61: Lucky Tiu
C62: Asst. Treasurer | G62: Treasurer | I62: Auditor | L62: President

Sheet Mar_2024_FR
C4: Our Lady of the Most Holy Rosary (Sub-Parish)
C5: Diamond Crest Village ,Brgy, San Manuel, San Jose DelMonte City, Bulacan
C7: FINANCIAL REPORT
C8: As of MARCH 31, 2024
C10: Cash Balance as of March 01, 2024 | K10: P | L10: 2139.25
C12: Add: Receipts for the month of March
C14: Mass Collections: | G14: (Net of Stipend)
H16: Collections | I16: Stipend | J16: Net Amount
E18: March | G18: 03 | H18: 2320 | I18: 150 | J18: =H18-I18 -> 2170
E19: March | G19: 10 | H19: 0 | I19: 0 | J19: =H19-I19 -> 0 | N19: No mass
E20: March | G20: 17 | H20: 1288 | I20: 0 | J20: =H20-I20 -> 1288
E21: March | G21: 31 | H21: =930 -> 930 | I21: 900 | J21: =H21-I21 -> 30
E23: Total | H23: =SUM(H18:H21) -> 4538 | I23: =SUM(I18:I21) -> 1050 | J23: =SUM(J18:J21) -> 3488
C25: Alay Kapwa Collections | J25: 10400
C27: Donations from Mass Intentions : (see Schedule A) | J27: 0
E29: Donations ( net of Stipend ) | J29: ='Mar_2024_Sched A'!I37 -> 700 | L29: =J23+J25+J29 -> 14588 | N29: 14438 | O29: =550-J29 -> -150
C31: Total Cash Available | K31: P | L31: =L29+L10 -> 16727.25
C33: Less: Expenses for the month of March
C35: Date | E35: PCV # | G35: Particulars | J35: Amount
C37: 03/06/2024 | G37: Utility Expenses (Meralco & Water Bills ) | J37: 1326.6
C38: 03/06/2024 | G38: Candles | J38: 141.1
C39: 03/23/2024 | G39: Battery Charger | J39: 699
C40: 03/24/2024 | G40: Dry Clean Services ( Sto. Entiero clothes) | J40: 400
C41: 03/26/2024 | G41: Food Expenses ( PABASA & VIGIL) | J41: 559.75
C42: 03/26/2024 | G42: Repairs of Hot and Cold Dispenser | J42: 250
C43: 03/30/2024 | G43: Food Sharing ( for SLR Parish ) | J43: =1300+200 -> 1500 | L43: =SUM(J37:J43) -> 4876.45
C45: Net of Expenses | L45: =L31-L43 -> 11850.8
C47: Less: Deposits for the month of March 2024 | L47: 882.55
C49: Cash Balance as of March 31, 2024 | K49: P | L49: =L45-L47 -> 10968.25 | N49: =L45-L47 -> 10968.25
C53: Cash in Bank as of February 29, 2024 | K53: P | L53: 59947.06
C55: Add: Deposits - March 2024 | L55: 882.55
C56: Interest ( Net of witholding tax ) | L56: =6.53-1.31 -> 5.22
C57: Cash in Bank as of March 31, 2024 | K57: P | L57: =SUM(L53:L56) -> 60834.83
C62: Prepared by: | G62: Checked by: | I62: Audited by: | L62: Noted by:
C64: Elvira Grafil | G64: Fely Rabano | I64: Tina Murla | L64: Lucky Tiu
C65: Asst. Treasurer | G65: Treasurer | I65: Auditor | L65: President

Sheet Mar_2024_Sched A
B2: Schedule A
B7: Our Lady of the Most Holy Rosary (Sub-Parish)
G8: Control File - Receipts
F9: For the month of March 2024
G11: DONATIONS (Mass Intentions:Thanksgiving, Souls, others) | H11: DONATIONS | I11: Net of Donations | J11: STIPEND from | L11: Total Stipend
B12: Date | D12: OR Number | F12: Donor | J12: Donations | K12: Mass Collections
B13: March
B14: 03 | D14: 2607 | F14: Chris Levi | G14: 100
B15: 03 | D15: 2608 | F15: Elmer Buere | G15: 100
B16: 03 | D16: 2609 | F16: Art de Leon | G16: 200
B17: 03 | D17: 2610 | F17: Emeld Torres | G17: 100
B18: 03 | D18: 2611 | F18: Gina | G18: 100
B19: 03 | D19: 2612 | F19: Fely Rabano | G19: 100
B20: 03 | D20: 2613 | F20: Abeles | G20: 150
B21: Sub-Total | G21: =SUM(G14:G20) -> 850 | I21: =G21-J21 -> 0 | J21: 850 | K21: 150 | L21: =J21+K21 -> 1000
B22: 17 | D22: 2605 | F22: Art de Leon & Family | G22: 200
B23: 17 | D23: 2614 | F23: Elmer Buere | G23: 100
B24: 17 | D24: 2615 | F24: Jane Pasamba | G24: 100
B25: 17 | D25: 2616 | F25: Thin | G25: 100
B26: 17 | D26: 2617 | F26: R. Calonge | G26: 100
B27: 17 | D27: 2618 | F27: Hilda | G27: 100
B28: 17 | D28: 2619 | F28: Abeles | G28: 150
B29: 17 | D29: 2620 | F29: Belma | G29: 100
B30: 17 | D30: 2621 | F30: Emelda | G30: 100
B31: Sub-Total | G31: =SUM(G22:G30) -> 1050 | I31: =G31-J31 -> 50 | J31: 1000 | K31: 0 | L31: =J31+K31 -> 1000
B32: 31 | D32: 2622 | F32: Calonge Family | G32: 100
B33: 31 | D33: 2623 | F33: Gina | G33: 100
B34: 31 | D34: No OR | F34: Terrie | G34: 500
B35: 31 | D35: No OR | F35: Abeles | G35: 50 | K35: 0
B36: Sub-Total | G36: =SUM(G32:G35) -> 750 | I36: =G36-J36 -> 650 | J36: 100 | K36: 900 | L36: =J36+K36 -> 1000
B37: TOTAL | G37: =G21+G31+G36 -> 2650 | I37: =I21+I31+I36 -> 700 | J37: =J21+J31+J36 -> 1950 | K37: =K21+K31+K36 -> 1050 | L37: =L21+L31+L36 -> 3000
I38: =G37-J37 -> 700
B46: Stipend for the month of March 2024
B48: Period covered | F48: Amount
B49: March | C49: 03 | F49: 1000
B50: March | C50: 10 | D50: No mass | F50: 0
B51: March | C51: 17 | F51: 1000
B52: March | C52: 31 | F52: 1000
B54: Total Stipend | F54: =SUM(F49:F52) -> 3000

Sheet April_2024_FR
C4: Our Lady of the Most Holy Rosary (Sub-Parish)
C5: Diamond Crest Village ,Brgy, San Manuel, San Jose DelMonte City, Bulacan
C7: FINANCIAL REPORT
C8: As of APRIL 30, 2024
C10: Cash Balance as of April 01, 2024 | K10: P | L10: 10968.25
C12: Add: Receipts for the month of April 2024
C14: Mass Collections: | G14: (Net of Stipend)
H16: Collections | I16: Stipend | J16: Net Amount
E18: April | G18: 07 | H18: 1265 | I18: 150 | J18: =H18-I18 -> 1115
E19: April | G19: 14 | H19: 881 | I19: 300 | J19: =H19-I19 -> 581
E20: April | G20: 21 | H20: 884 | I20: 50 | J20: =H20-I20 -> 834
E21: April | G21: 28 | H21: 795 | I21: 300 | J21: =H21-I21 -> 495
E23: Total | H23: =SUM(H18:H21) -> 3825 | I23: =SUM(I18:I21) -> 800 | J23: =SUM(J18:J21) -> 3025
C27: Donations from Mass Intentions : (see Schedule A)
E29: Donations ( net of Stipend ) | J29: ='April_2024_Sched A'!I45 -> 0 | L29: =J29+J23 -> 3025
C31: Total Cash Available | K31: P | L31: =L10+L29 -> 13993.25
C34: Less: Expenses for the month of April
C36: Date | E36: PCV # | G36: Particulars | J36: Amount
C38: April 14, 2024 | G38: Donations (Abuloy to Leah's sister -Mindanao) | J38: 500
C39: April 16, 2024 | G39: Utility Expenses (Meralco & Water Bills ) | J39: 1112.85 | L39: =J38+J39 -> 1612.85
C41: Net of Expenses | L41: =L31-L39 -> 12380.4
C43: Less: Deposits for the month of April 2024 | L43: 1256.7
C45: Cash Balance as of April 30, 2024 | K45: P | L45: =L41-L43 -> 11123.7
C49: Cash in Bank as of March 31, 2024 | K49: P | L49: 60834.83
C51: Add: Deposits - April 2024 | L51: 1256.7
C52: Interest ( Net of witholding tax ) | L52: =6.42-1.28 -> 5.14
C53: Cash in Bank as of April 30, 2024 | K53: P | L53: =SUM(L49:L52) -> 62096.67
C58: Prepared by: | G58: Checked by: | I58: Audited by: | L58: Noted by:
C60: Elvira Grafil | G60: Fely Rabano | I60: Tina Murla | L60: Lucky Tiu
C61: Asst. Treasurer | G61: Treasurer | I61: Auditor | L61: President

Sheet April_2024_Sched A
B2: Schedule A
B7: Our Lady of the Most Holy Rosary (Sub-Parish)
G8: Control File - Receipts
F9: For the month of April 2024
G11: DONATIONS (Mass Intentions:Thanksgiving, Souls, others) | H11: DONATIONS | I11: Net of Donations | J11: STIPEND from | L11: Total Stipend
B12: Date | D12: OR Number | F12: Donor | J12: Donations | K12: Mass Collections
B13: April
B14: 07 | D14: 2623 | F14: Gina | G14: 100
B15: 07 | D15: 2624 | F15: Imelda | G15: 100
B16: 07 | D16: 2625 | F16: Art de Leon | G16: 200
B17: 07 | D17: 2626 | F17: Hilda | G17: 150
B18: 07 | D18: 2627 | F18: Beng Grafil | G18: 100
B19: 07 | D19: 2628 | F19: Elmer Buere | G19: 100
B20: 07 | D20: 2629 | F20: Baby | G20: 100
B21: Sub-Total | G21: =SUM(G14:G20) -> 850 | I21: =G21-J21 -> 0 | J21: 850 | K21: 150 | L21: =J21+K21 -> 1000
B22: 14 | D22: 2630 | F22: Jane Pasamba | G22: 100
B23: 14 | D23: 2631 | F23: Beng Grafil | G23: 100
B24: 14 | D24: 2632 | F24: Juvy | G24: 100
B25: 14 | D25: 2633 | F25: Abeles | G25: 150
B26: 14 | D26: 2634 | F26: Lea | G26: 50
B27: 14 | D27: 2635 | F27: Irene | G27: 100
B28: 14 | D28: - | F28: No Official Receipt | G28: 100
B29: Sub-Total | G29: =SUM(G22:G28) -> 700 | I29: =G29-J29 -> 0 | J29: 700 | K29: 300 | L29: =J29+K29 -> 1000
B30: 21 | D30: 2636 | F30: Beng Grafil | G30: 100
B31: 21 | D31: 2637 | F31: Gina | G31: 100
B32: 21 | D32: 2638 | F32: Galang Store | G32: 50
B33: 21 | D33: 2639 | F33: Art de Leon & Family | G33: 500
B34: 21 | D34: 2640 | F34: Elmer Buere | G34: 100
B35: 21 | D35: 2641 | F35: Irene | G35: 100
B36: Sub-Total | G36: =SUM(G30:G35) -> 950 | I36: =G36-J36 -> 0 | J36: 950 | K36: 50 | L36: =J36+K36 -> 1000
B37: 28 | D37: 2642 | F37: Fely Rabano | G37: 100
B38: 28 | D38: 2643 | F38: Thelma Lara | G38: 50
B39: 28 | D39: 2644 | F39: Art de Leon & Family | G39: 200
B40: 28 | D40: 2645 | F40: Loira | G40: 100
B41: 28 | D41: 2646 | F41: Jane | G41: 100
B42: 28 | D42: 2647 | F42: Elmer Buere | G42: 100
B43: 28 | D43: 2648 | F43: Susan | G43: 50 | K43: 0
B44: Sub-Total | G44: =SUM(G37:G43) -> 700 | I44: =G44-J44 -> 0 | J44: 700 | K44: 300 | L44: =J44+K44 -> 1000
B45: TOTAL | G45: =G21+G29+G36+G44 -> 3200 | I45: =I21+I36+I44 -> 0 | J45: =J21+J29+J36+J44 -> 3200 | K45: =K21+K29+K36+K44 -> 800 | L45: =L21+L29+L36+L44 -> 4000
B54: Stipend for the month of April 2024
...

Sheet May-2024_FR
C4: Our Lady of the Most Holy Rosary (Sub-Parish)
C5: Diamond Crest Village ,Brgy, San Manuel, San Jose DelMonte City, Bulacan
C7: FINANCIAL REPORT
C8: As of MAY 31, 2024
C10: Cash Balance as of May 01, 2024 | L10: P | M10: 11123.7
C12: Add: Receipts for the month of May 2024
C14: Mass Collections: | G14: (Net of Stipend)
H16: Collections | I16: Stipend | J16: Others | K16: Net Amount
E18: May | G18: 05 | H18: 1158 | I18: 200 | J18: 300 | K18: =H18-I18-J18 -> 658
E19: May | G19: 12 | H19: 909 | I19: 0 | J19: 0 | K19: =H19-I19 -> 909
E20: May | G20: 19 | H20: 892 | I20: 500 | J20: 0 | K20: =H20-I20 -> 392
E21: May | G21: 26 | H21: 806 | I21: 400 | J21: 0 | K21: =H21-I21 -> 406
E23: Total | H23: =SUM(H18:H21) -> 3765 | I23: =SUM(I18:I21) -> 1100 | J23: =SUM(J18:J21) -> 300 | K23: =SUM(K18:K21) -> 2365
C27: Donations from Mass Intentions : (see Schedule A)
E29: Donations ( net of Stipend ) | K29: ='May-2024-Sched A'!I49 -> 600 | M29: =K29+K23 -> 2965 | O29: 2915 | P29: =O29-M29 -> -50
C31: Add: Cash withdrawal - May 24, 2024 | M31: 9000
C33: Total Cash Available | L33: P | M33: =M10+M29+M31 -> 23088.7
C38: Less: Expenses for the month of May
C40: Date | E40: PCV # | G40: Particulars | K40: Amount
C42: May 9, 2024 | G42: Dry Clean Expenses ( Mama Mary Gowns) | K42: 400
C43: May 21, 2024 | G43: Utility Expenses (Meralco & Water Bills ) | K43: =976.8+168.8 -> 1145.6
C44: May 21, 2024 | G44: Materials for "Luhuran" | K44: 115
C45: May 24,2024 | G45: Labor/Materials and Repairs Expenses | K45: 3000
C46: May 28, 2024 | G46: Candles | K46: 212.25
C47: May 29, 2024 | G47: Stipend for Novenario (Flores de Maria) | K47: 3000 | M47: =SUM(K42:K47) -> 7872.85
C49: Net of Expenses | M49: =M33-M47 -> 15215.85
C51: Less: Deposits for the month of May 2024 | M51: 9711.55
C53: Cash Balance as of May31, 2024 | L53: P | M53: =M49-M51 -> 5504.3 | O53: =M49-M51 -> 5504.3
C57: Cash in Bank as of April 30, 2024 | L57: P | M57: 62096.67
C59: Add: Deposits - May 21, 2024 | M59: 9711.55
C60: Interest ( Net of witholding tax ) | M60: =6.8-1.36 -> 5.44
C61: Less: Withdrawal - May 24, 2024 | M61: -9000
C62: Cash in Bank as of Mayl 31, 2024 | L62: P | M62: =SUM(M57:M61) -> 62813.66
C67: Prepared by: | G67: Checked by: | I67: Audited by: | M67: Noted by:
C69: Elvira Grafil | G69: Fely Rabano | I69: Tina Murla | M69: Lucky Tiu
C70: Asst. Treasurer | G70: Treasurer | I70: Auditor | M70: President

Sheet May-2024-Sched A
B2: Schedule A
B7: Our Lady of the Most Holy Rosary (Sub-Parish)
G8: Control File - Receipts
F9: For the month of May 2024
G11: DONATIONS (Mass Intentions:Thanksgiving, Souls, others) | H11: DONATIONS | I11: Net of Donations | J11: STIPEND from | L11: Total Stipend
B12: Date | D12: OR Number | F12: Donor | J12: Donations | K12: Mass Collections
B13: May
B14: 05 | D14: 2649 | F14: Lucy | G14: 50
B15: 05 | D15: 2650 | F15: Ebony | G15: 100
B16: 05 | D16: 2651 | F16: Art de Leon & Family | G16: 100
B17: 05 | D17: 2652 | F17: Calonge Family | G17: 100
B18: 05 | D18: 2653 | F18: Eloisa | G18: 100
B19: 05 | D19: 2654 | F19: Beng Grafil | G19: 100
B20: 05 | D20: 2655 | F20: Helen | G20: 100
B21: 05 | D21: 2656 | F21: Helen | G21: 100
B22: 05 | D22: 2657 | F22: Elmer Buere | G22: 100
B23: Sub-Total | G23: =SUM(G14:G22) -> 850 | I23: =G23-J23 -> 50 | J23: 800 | K23: 200 | L23: =J23+K23 -> 1000
B24: 12 | D24: 2658 | F24: Tina Murla | G24: 500
B25: 12 | D25: 2659 | F25: Galang Family | G25: 50
B26: 12 | D26: 2660 | F26: Beng Grafil | G26: 150
B27: 12 | D27: 2661 | F27: Jane Pasamba | G27: 100
B28: 12 | D28: 2662 | F28: Lucy Sararosing Family | G28: 100
B29: 12 | D29: 2663 | F29: Gina | G29: 100
B30: 12 | D30: 2664 | F30: Ebony | G30: 100
B31: 12 | D31: 2665 | F31: Banog Family | G31: 100
B32: 12 | D32: 2666 | F32: Elmer Buere | G32: 100
B33: 12 | D33: 2667 | F33: Irene Masong | G33: 100
B34: 12 | D34: 2668 | F34: Aveles Family | G34: 150
B35: Sub-Total | G35: =SUM(G24:G34) -> 1550 | I35: =G35-J35 -> 550 | J35: 1000 | K35: 0 | L35: =J35+K35 -> 1000
B36: 19 | D36: 2669 | F36: Art de Leon | G36: 100
B37: 19 | D37: 2670 | F37: Beng Grafil | G37: 100
B38: 19 | D38: 2671 | F38: Eloisa | G38: 100
B39: 19 | D39: 2672 | F39: Susan | G39: 100
B40: 19 | D40: 2673 | F40: Rose | G40: 100
B41: Sub-Total | G41: =SUM(G36:G40) -> 500 | I41: =G41-J41 -> 0 | J41: 500 | K41: 500 | L41: =J41+K41 -> 1000
B42: 26 | D42: 2674 | F42: Calonge Family | G42: 100
B43: 26 | D43: 2675 | F43: Jane Pasamba | G43: 100
B44: 26 | D44: 2676 | F44: Susan | G44: 100
B45: 26 | D45: 2677 | F45: Elmer Buere | G45: 100
B46: 26 | D46: 2678 | F46: Hilda | G46: 100
...

Sheet June-2024-FR
C4: Our Lady of the Most Holy Rosary (Sub-Parish)
C5: Diamond Crest Village ,Brgy, San Manuel, San Jose DelMonte City, Bulacan
C7: FINANCIAL REPORT
C8: As of JUNE 30, 2024
C10: Cash Balance as of June 01, 2024 | L10: P | M10: 5504.3
C12: Add: Receipts for the month of June 2024
C14: Mass Collections: | G14: (Net of Stipend)
H16: Collections | I16: Stipend | J16: Others | K16: Net Amount
E18: June | G18: 09 | H18: 3258 | I18: 0 | J18: 0 | K18: =H18-I18-J18 -> 3258
E19: June | G19: 16 | H19: 903 | I19: 150 | J19: 0 | K19: =H19-I19 -> 753
E20: June | G20: 23 | H20: 1125 | I20: 300 | J20: 0 | K20: =H20-I20 -> 825
E21: June | G21: 30 | H21: 1024 | I21: 0 | J21: 0 | K21: =H21-I21 -> 1024
E23: Total | H23: =SUM(H18:H21) -> 6310 | I23: =SUM(I18:I21) -> 450 | J23: =SUM(J18:J21) -> 0 | K23: =SUM(K18:K21) -> 5860
C27: Donations from Mass Intentions : (see Schedule A)
E29: Donations ( net of Stipend ) | K29: ='June-2024-SchedA'!I50 -> 120 | M29: =K29+K23 -> 5980 | O29: 5960 | P29: =M29-O29 -> 20
C31: Add: Cash withdrawal | M31: 0
C33: Total Cash Available | L33: P | M33: =M10+M29+M31 -> 11484.3
C38: Less: Expenses for the month of June 2024
C40: Date | E40: PCV # | G40: Particulars | K40: Amount
C42: June 01, 2024 | G42: Tarpaulin ( Signage for No Mass ) | K42: 150
C43: June 16, 2024 | G43: Father's Day gift ( for Father Von ) | K43: 1000
C44: June 18, 2024 | G44: Utility Expenses ( Water Bills share for 2 months ) | K44: =300+300 -> 600
C45: June 20, 2024 | G45: Battery for Laptop used at Chapel | K45: 239
C46: June 29, 2024 | G46: Candles | K46: 210.15
C47: June 30, 2024 | G47: Flowers at SLR Parish for the month of June 2024 | K47: 700 | M47: =SUM(K42:K47) -> 2899.15
C49: Net of Expenses | M49: =M33-M47 -> 8585.15
C51: Less: Deposits for the month of June 2024 | M51: 1412.15
C53: Cash Balance as of June 30, 2024 | L53: P | M53: =M49-M51 -> 7173 | O53: =M49-M51 -> 7173
C57: Cash in Bank as of May 31, 2024 | L57: P | M57: 62813.66
C59: Add: Deposits - June 18, 2024 | M59: 1412.15
C60: Interest ( Net of witholding tax ) | M60: =6.61-1.32 -> 5.29
C61: Less: Withdrawal | M61: 0
C62: Cash in Bank as of June 30, 2024 | L62: P | M62: =SUM(M57:M61) -> 64231.1
C67: Prepared by: | G67: Checked by: | I67: Audited by: | M67: Noted by:
C69: Elvira Grafil | G69: Fely Rabano | I69: Tina Murla | M69: Lucky Tiu
C70: Asst. Treasurer | G70: Treasurer | I70: Auditor | M70: President

Sheet June-2024-SchedA
B2: Schedule A
B7: Our Lady of the Most Holy Rosary (Sub-Parish)
G8: Control File - Receipts
F9: For the month of June 2024
G11: DONATIONS (Mass Intentions:Thanksgiving, Souls, others) | H11: DONATIONS | I11: Net of Donations | J11: STIPEND from | L11: Total Stipend
B12: Date | D12: OR Number | F12: Donor | J12: Donations | K12: Mass Collections
B13: June
B14: 09 | D14: 2680 | F14: Neri | G14: 100
B15: 09 | D15: 2681 | F15: Gina | G15: 100
B16: 09 | D16: 2682 | F16: Elmer Buere | G16: 100
B17: 09 | D17: 2683 | F17: Beng Grafil | G17: 100
B18: 09 | D18: 2684 | F18: Eloisa | G18: 100
B19: 09 | D19: 2685 | F19: Art De Leon | G19: 200
B20: 09 | D20: 2686 | F20: Jane Pasamba | G20: 100
B21: 09 | D21: 2687 | F21: Sola | G21: 100
B22: 09 | D22: 2688 | F22: Annie | G22: 20
B23: 09 | D23: 2689 | F23: Helen | G23: 150
B24: 09 | D24: 2690 | F24: Hilda | G24: 50
B25: Sub-Total | G25: =SUM(G14:G24) -> 1120 | I25: =G25-J25 -> 120 | J25: 1000 | K25: 0 | L25: =J25+K25 -> 1000
B26: 16 | D26: 2691 | F26: Fely Rabano | G26: 100
B27: 16 | D27: 2692 | F27: Gina | G27: 100
B28: 16 | D28: 2693 | F28: Art De Leon | G28: 200
B29: 16 | D29: 2694 | F29: Lucy Sararosing Family | G29: 100
B30: 16 | D30: 2695 | F30: Eloisa | G30: 100
B31: 16 | D31: 2696 | F31: Irene | G31: 100
B32: 16 | D32: 2697 | F32: Susan | G32: 50
B33: 16 | D33: 2698 | F33: Juvy | G33: 100
B34: Sub-Total | G34: =SUM(G26:G33) -> 850 | I34: =G34-J34 -> 0 | J34: 850 | K34: 150 | L34: =J34+K34 -> 1000
B35: 23 | D35: 2699 | F35: Art De Leon | G35: 200
B36: 23 | D36: 2700 | F36: Jane Pasamba | G36: 100
B37: 23 | D37: 2701 | F37: Helen | G37: 100
B38: 23 | D38: 2702 | F38: Eloisa | G38: 100
B39: 23 | D39: - | F39: No Official Receipt | G39: 200
B40: Sub-Total | G40: =SUM(G35:G39) -> 700 | I40: =G40-J40 -> 0 | J40: 700 | K40: 300 | L40: =J40+K40 -> 1000
B41: 30 | D41: 2703 | F41: Lucia Gacomo | G41: 100
B42: 30 | D42: 2704 | F42: Beng Grafil | G42: 100
B43: 30 | D43: 2705 | F43: Reylyn Calonge | G43: 100
B44: 30 | D44: 2706 | F44: Elmer Buere | G44: 100
B45: 30 | D45: 2707 | F45: Banog Family | G45: 100
B46: 30 | D46: 2708 | F46: Unused OR(see July 7) | G46: 0
...

Sheet July-2024-FR
C4: Our Lady of the Most Holy Rosary (Sub-Parish)
C5: Diamond Crest Village ,Brgy, San Manuel, San Jose DelMonte City, Bulacan
C7: FINANCIAL REPORT
C8: As of JULY 31, 2024
C10: Cash Balance as of July 01, 2024 | L10: P | M10: 7173
C12: Add: Receipts for the month of July 2024
C14: Mass Collections: | G14: (Net of Stipend)
H16: Collections | I16: Stipend | J16: Others | K16: Net Amount
E18: July | G18: 07 | H18: 1495 | I18: 700 | J18: 0 | K18: =H18-I18-J18 -> 795
E19: July | G19: 14 | H19: 1130 | I19: 100 | J19: 0 | K19: =H19-I19 -> 1030
E20: July | G20: 21 | H20: 1385 | I20: 400 | J20: 0 | K20: =H20-I20 -> 985
E21: July | G21: 28 | H21: 1004 | I21: 150 | J21: 0 | K21: =H21-I21 -> 854
E23: Total | H23: =SUM(H18:H21) -> 5014 | I23: =SUM(I18:I21) -> 1350 | J23: =SUM(J18:J21) -> 0 | K23: =SUM(K18:K21) -> 3664
C27: Donations from Mass Intentions : (see Schedule A)
E29: Donations ( net of Stipend ) | K29: ='July-2024-Sched A'!I42 -> 0 | M29: =K29+K23 -> 3664
C31: Add: Cash withdrawal | M31: 0
C33: Total Cash Available | L33: P | M33: =M10+M29+M31 -> 10837
C38: Less: Expenses for the month of July 2024
C40: Date | E40: PCV # | G40: Particulars | K40: Amount
C42: July 17, 2024 | G42: Utility Expenses ( Meralco Bill - May 21-June 20 ) | K42: 783.38
C43: July 27, 2024 | G43: Labor/Materials and Repairs Expenses ( repair of ceiling ) | K43: 635 | M43: =K42+K43 -> 1418.38
C44: June 18, 2024 | G44: Utility Expenses ( Water Bills share for 2 months ) | K44: 0
C45: June 20, 2024 | G45: Battery for Laptop used at Chapel | K45: 0
C46: June 29, 2024 | G46: Candles | K46: 0
C47: June 30, 2024 | G47: Flowers at SLR Parish for the month of June 2024 | K47: 0 | M47: =SUM(K42:K47) -> 1418.38
C49: Net of Expenses | M49: =M33-M43 -> 9418.62
C51: Less: Deposits for the month of July 2024 | M51: =1193+2899.15 -> 4092.15
C53: Cash Balance as of July 31, 2024 | L53: P | M53: =M49-M51 -> 5326.47
C57: Cash in Bank as of June 30, 2024 | L57: P | M57: 64231.1
C59: Add: Deposits - July 17, 2024 | M59: 1193
C60: Deposits - July 22, 2024 | M60: 2899.15
C61: Interest ( Net of witholding tax ) | M61: =7.08-1.42 -> 5.66
C62: Less: Withdrawal | M62: 0
C63: Cash in Bank as of July 31, 2024 | L63: P | M63: =SUM(M57:M62) -> 68328.91
C68: Prepared by: | G68: Checked by: | I68: Audited by: | M68: Noted by:
C70: Elvira Grafil | G70: Fely Rabano | I70: Tina Murla | M70: Lucky Tiu
C71: Asst. Treasurer | G71: Treasurer | I71: Auditor | M71: President

Sheet July-2024-Sched A
B2: Schedule A
B7: Our Lady of the Most Holy Rosary (Sub-Parish)
G8: Control File - Receipts
F9: For the month of July 2024
G11: DONATIONS (Mass Intentions:Thanksgiving, Souls, others) | H11: DONATIONS | I11: Net of Donations | J11: STIPEND from | L11: Total Stipend
B12: Date | D12: OR Number | F12: Donor | J12: Donations | K12: Mass Collections
B13: July
B14: 07 | D14: 2708 | F14: Jane Pasamba | G14: 100
B15: 07 | D15: 2711 | F15: Elmer Buere | G15: 100
B16: 07 | D16: =1+D15 -> 2712 | F16: Maricel | G16: 100
B17: Sub-Total | G17: =SUM(G14:G16) -> 300 | I17: =G17-J17 -> 0 | J17: 300 | K17: 700 | L17: =J17+K17 -> 1000
B18: 14 | D18: 2713 | F18: Josefina Avila | G18: 100
B19: 14 | D19: =1+D18 -> 2714 | F19: Elmer Buere | G19: 100
B20: 14 | D20: =1+D19 -> 2715 | F20: Thelma | G20: 100
B21: 14 | D21: =1+D20 -> 2716 | F21: Thin Tapaoan | G21: 100
B22: 14 | D22: =1+D21 -> 2717 | F22: Eloisa | G22: 100
B23: 14 | D23: =1+D22 -> 2718 | F23: Beng Grafil | G23: 100
B24: 14 | D24: =1+D23 -> 2719 | F24: Baby Boris | G24: 200
B25: 14 | D25: =1+D24 -> 2720 | F25: Irene | G25: 100
B26: Sub-Total | G26: =SUM(G18:G25) -> 900 | I26: =G26-J26 -> 0 | J26: 900 | K26: 100 | L26: =J26+K26 -> 1000
B27: 21 | D27: 2721 | F27: Hilda | G27: 200
B28: 21 | D28: =1+D27 -> 2722 | F28: Elmer Buere | G28: 100
B29: 21 | D29: =1+D28 -> 2723 | F29: Jane Pasamba | G29: 100
B30: 21 | D30: =1+D29 -> 2724 | F30: Thin Tapaoan | G30: 100
B31: 21 | D31: =1+D30 -> 2725 | F31: Eloisa | G31: 100
B32: Sub-Total | G32: =SUM(G27:G31) -> 600 | I32: =G32-J32 -> 0 | J32: 600 | K32: 400 | L32: =J32+K32 -> 1000
B33: 28 | D33: 2726 | F33: Beng Grafil | G33: 100
B34: 28 | D34: =1+D33 -> 2727 | F34: Lucy S, & Atienza family | G34: 150
B35: 28 | D35: =1+D34 -> 2728 | F35: Billy Lara | G35: 100
B36: 28 | D36: =1+D35 -> 2729 | F36: Thin Tapaoan | G36: 100
B37: 28 | D37: =1+D36 -> 2730 | F37: Lucia Gacuma | G37: 100
B38: 28 | D38: =1+D37 -> 2731 | F38: Banog family | G38: 100
B39: 28 | D39: =1+D38 -> 2732 | F39: Baby Boris | G39: 100
B40: 28 | D40: =1+D39 -> 2733 | F40: Elmer Buere & family | G40: 100
B41: Sub-Total | G41: =SUM(G33:G40) -> 850 | I41: =G41-J41 -> 0 | J41: 850 | K41: 150 | L41: =J41+K41 -> 1000
B42: TOTAL | G42: =G17+G26+G32+G41 -> 2650 | I42: =I17+I32+I26+I41 -> 0 | J42: =J17+J26+J32+J41 -> 2650 | K42: =K17+K26+K32+K41 -> 1350 | L42: =L17+L26+L32+L41 -> 4000
B51: Stipend for the month of July 2024
B53: Period covered | F53: Amount
B54: July | C54: 07 | F54: 1000
B55: July | C55: 14 | F55: 1000
...

Sheet Aug-2024-FR
C4: Our Lady of the Most Holy Rosary (Sub-Parish)
C5: Diamond Crest Village ,Brgy, San Manuel, San Jose DelMonte City, Bulacan
C7: FINANCIAL REPORT
C8: As of AUGUST 31, 2024
C10: Cash Balance as of August 01, 2024 | L10: P | M10: 5326.47
C12: Add: Receipts for the month of August 2024
C14: Mass Collections: | G14: (Net of Stipend)
H16: Collections | I16: Stipend | J16: Others | K16: Net Amount
E18: August | G18: 04 | H18: 950 | I18: 500 | J18: 0 | K18: =H18-I18-J18 -> 450
E19: August | G19: 11 | H19: 1276 | I19: 800 | J19: 0 | K19: =H19-I19 -> 476
E20: August | G20: 18 | H20: 2122 | I20: 250 | J20: 0 | K20: =H20-I20 -> 1872
E21: August | G21: 25 | H21: 1182 | I21: 450 | J21: 0 | K21: =H21-I21 -> 732
E23: Total | H23: =SUM(H18:H21) -> 5530 | I23: =SUM(I18:I21) -> 2000 | J23: =SUM(J18:J21) -> 0 | K23: =SUM(K18:K21) -> 3530
C27: Donations from Mass Intentions : (see Schedule A)
E29: Donations ( net of Stipend ) | K29: ='[1]July-2024-Sched A'!I42 -> 0 | M29: =K29+K23 -> 3530
C31: Add: Cash withdrawal | M31: 0
C33: Total Cash Available | L33: P | M33: =M10+M29+M31 -> 8856.47
C38: Less: Expenses for the month of August 2024
C40: Date | E40: PCV # | G40: Particulars | K40: Amount
C42: August 4 | G42: Parol ( partial payment ) | K42: 1000
C43: August 8 | G43: Utility Expenses ( Meralco Bill - June 21 to July 20 ) | K43: 800
C44: August 9 | G44: Laundry Expenses ( Dry Clean - Santo clothes ) | K44: 200
C45: August 10 | G45: Labor expenses ( Sub-meter removal ) | K45: 500
C46: August 11 | G46: Labor expenses ( Fabrication of metal cabinet ) | K46: 500
C47: August 23 | G47: Food expenses ( Food share for Father Von's anniversary ) | K47: 1250
C48: August 25 | G48: Donation ( Abuloy to former SPPC Choir) | K48: 1500 | M48: =SUM(K42:K48) -> 5750
C49: June 18, 2024 | G49: Utility Expenses ( Water Bills share for 2 months ) | K49: 0
C50: June 20, 2024 | G50: Battery for Laptop used at Chapel | K50: 0
C51: June 29, 2024 | G51: Candles | K51: 0
C52: June 30, 2024 | G52: Flowers at SLR Parish for the month of June 2024 | K52: 0 | M52: =SUM(K42:K52) -> 5750
C54: Net of Expenses | M54: =M33-M48 -> 3106.47
C56: Less: Deposits for the month of August 2024 | M56: 3080.85
C58: Cash Balance as of August 31, 2024 | L58: P | M58: =M54-M56 -> 25.62
C62: Cash in Bank as of July 31, 2024 | L62: P | M62: 68328.91
C64: Add: Deposits - August 28, 2024 | M64: 3080.85
C65: Interest ( Net of witholding tax ) | M65: =7.39-1.48 -> 5.91
C66: Less: Withdrawal | M66: 0
C67: Cash in Bank as of August 31, 2024 | L67: P | M67: =SUM(M62:M66) -> 71415.67
C72: Prepared by: | G72: Checked by: | I72: Audited by: | M72: Noted by:
C74: Elvira Grafil | G74: Fely Rabano | I74: Tina Murla | M74: Lucky Tiu
...

Sheet Aug-2024-Sched A
B2: Schedule A
B7: Our Lady of the Most Holy Rosary (Sub-Parish)
G8: Control File - Receipts
F9: For the month of August 2024
G11: DONATIONS (Mass Intentions:Thanksgiving, Souls, others) | H11: DONATIONS | I11: Net of Donations | J11: STIPEND from | L11: Total Stipend
B12: Date | D12: OR Number | F12: Donor | J12: Donations | K12: Mass Collections
B13: August
B14: 04 | D14: 2734 | F14: Jane Pasamba | G14: 100
B15: 04 | D15: 2735 | F15: Elmer Buere | G15: 100
B16: 04 | D16: 2736 | F16: Beng Grafil | G16: 100
B17: 04 | D17: 2737 | F17: Eloisa | G17: 100
B18: 04 | D18: 2738 | F18: Relyne Calonge | G18: 100
B19: Sub-Total | G19: =SUM(G14:G18) -> 500 | I19: 0 | J19: 500 | K19: 500 | L19: =J19+K19 -> 1000
B20: 11 | D20: 2739 | F20: Meldie | G20: 100
B21: 11 | D21: =1+D20 -> 2740 | F21: Eloisa | G21: 100
B22: Sub-Total | G22: =SUM(G20:G21) -> 200 | I22: =G22-J22 -> 0 | J22: 200 | K22: 800 | L22: =J22+K22 -> 1000
B23: 18 | D23: 2741 | F23: Gina | G23: 100
B24: 18 | D24: =1+D23 -> 2742 | F24: Jane Pasamba | G24: 200
B25: 18 | D25: =1+D24 -> 2743 | F25: Susan | G25: 50
B26: 18 | D26: =1+D25 -> 2744 | F26: Elmer Buere | G26: 100
B27: 18 | D27: =1+D26 -> 2745 | F27: Rani | G27: 200
B28: 18 | D28: =1+D27 -> 2746 | F28: Eloisa | G28: 100
B29: Sub-Total | G29: =SUM(G23:G28) -> 750 | I29: =G29-J29 -> 0 | J29: 750 | K29: 250 | L29: =J29+K29 -> 1000
B30: 25 | D30: 2747 | F30: Mrs. Salas | G30: 100
B31: 25 | D31: =1+D30 -> 2748 | F31: Elmer Buere | G31: 100
B32: 25 | D32: =1+D31 -> 2749 | F32: Susan | G32: 50
B33: 25 | D33: =1+D32 -> 2750 | F33: Beng Grafil | G33: 100
B34: 25 | D34: =1+D33 -> 2751 | F34: Eloisa | G34: 100
B35: 28 | D35: =1+D34 -> 2752 | F35: Baby Boris | G35: 100
B36: Sub-Total | G36: =SUM(G30:G35) -> 550 | I36: =G36-J36 -> 0 | J36: 550 | K36: 450 | L36: =J36+K36 -> 1000
B37: TOTAL | G37: =G19+G22+G29+G36 -> 2000 | I37: =I19+I29+I22+I36 -> 0 | J37: =J19+J22+J29+J36 -> 2000 | K37: =K19+K22+K29+K36 -> 2000 | L37: =L19+L22+L29+L36 -> 4000
B46: Stipend for the month of August 2024
B48: Period covered | F48: Amount
B49: August | C49: 04 | F49: 1000
B50: August | C50: 11 | F50: 1000
B51: August | C51: 18 | F51: 1000
B52: August | C52: 25 | F52: 1000
B54: Total Stipend | F54: =SUM(F49:F52) -> 4000

Sheet Sept-2024-FR
C4: Our Lady of the Most Holy Rosary (Sub-Parish)
C5: Diamond Crest Village ,Brgy, San Manuel, San Jose DelMonte City, Bulacan
C7: FINANCIAL REPORT
C8: As of September 30, 2024
C10: Cash Balance as of September 01, 2024 | L10: P | M10: 25.62
C12: Add: Receipts for the month of September 2024
C14: Mass Collections: | G14: (Net of Stipend)
H16: Collections | I16: Stipend | J16: Others | K16: Net Amount
E18: September | G18: 01 | H18: 1881 | I18: 700 | J18: 0 | K18: =H18-I18-J18 -> 1181
E19: September | G19: 08 | H19: 2214 | I19: 450 | J19: 0 | K19: =H19-I19 -> 1764
E20: September | G20: 15 | H20: 1200 | I20: 600 | J20: 0 | K20: =H20-I20 -> 600
E21: September | G21: 22 | H21: 1210 | I21: 0 | J21: 0 | K21: =H21-I21 -> 1210
E23: Total | H23: =SUM(H18:H21) -> 6505 | I23: =SUM(I18:I21) -> 1750 | J23: =SUM(J18:J21) -> 0 | K23: =SUM(K18:K21) -> 4755 | O23: =H23-I23 -> 4755
C27: Donations from Mass Intentions : (see Schedule A)
E29: Donations ( net of Stipend ) | K29: ='Sept-2024-Sched A'!I41 -> 950 | M29: =K29+K23 -> 5705
C31: Add: Cash withdrawal | M31: 0
C33: Total Cash Available | L33: P | M33: =M10+M29+M31 -> 5730.62
C38: Less: Expenses for the month of September 2024
C40: Date | E40: PCV # | G40: Particulars | K40: Amount
C42: September 7 | G42: Battery for wireless microphones | K42: 119
C43: September 13 | G43: Cleaning materials ( brooms and walis ting-ting) | K43: 170
C44: September 14 | G44: Tarpaulin for Fiesta at SLRP | K44: 500
C45: September 17 | G45: Electricity Expenses ( Meralco Bill - July21 to August 20 ) | K45: 668.6
C46: September 17 | G46: Water Expenses ( Billing period - July 12-August 11 ) | K46: 632.85
C47: September 20 | G47: Transporation Expenses ( Convention Center re: Gabi ng Parokya) | K47: 1000
C48: September 22 | G48: Expenses for the Cleaning of Chapel's lectric fans | K48: 500
C49: September 24 | G49: Purchase of chlorine used outside the chapel | K49: 200
C50: September 24 | G50: Mass Stipend ( Novena mass - SPPC sponsor ) | K50: 2500
C51: September 20 | G51: Food share for the guest Priest ( Novena mass ) | K51: 900 | M51: =SUM(K42:K51) -> 7190.45
C52: June 18, 2024 | G52: Utility Expenses ( Water Bills share for 2 months ) | K52: 0
C53: June 20, 2024 | G53: Battery for Laptop used at Chapel | K53: 0
C54: June 29, 2024 | G54: Candles | K54: 0
C55: June 30, 2024 | G55: Flowers at SLR Parish for the month of June 2024 | K55: 0 | M55: =SUM(K46:K55) -> 5732.85
C57: Net of Expenses | M57: =M33-M51 -> -1459.83
C59: Less: Deposits for the month of September 2024 | M59: 0
C61: Cash Balance as of September 30, 2024 | L61: P | M61: =M57-M59 -> -1459.83
C65: Cash in Bank as of August 31, 2024 | L65: P | M65: 71415.67
C67: Add: Deposits - | M67: 0
C68: Interest ( Net of witholding tax ) | M68: =7.44-1.49 -> 5.95
C69: Less: Withdrawal | M69: 0
...

Sheet Sept-2024-Sched A
B2: Schedule A
B7: Our Lady of the Most Holy Rosary (Sub-Parish)
G8: Control File - Receipts
F9: For the month of September 2024
G11: DONATIONS (Mass Intentions:Thanksgiving, Souls, others) | H11: DONATIONS | I11: Net of Donations | J11: STIPEND from | L11: Total Stipend
B12: Date | D12: OR Number | F12: Donor | J12: Donations | K12: Mass Collections
B13: September
B14: 01 | D14: 2753 | F14: Jane Pasamba | G14: 100
B15: 01 | D15: =1+D14 -> 2754 | F15: Elmer Buere | G15: 100
B16: 01 | D16: =1+D15 -> 2755 | F16: Eloisa | G16: 100
B17: Sub-Total | G17: =SUM(G14:G16) -> 300 | I17: =G17-J17 -> 0 | J17: 300 | K17: 700 | L17: =J17+K17 -> 1000
B18: 08 | D18: 2756 | F18: Lucy Saramosing | G18: 150
B19: 08 | D19: =1+D18 -> 2757 | F19: Elmer Buere | G19: 100
B20: 08 | D20: =1+D19 -> 2758 | F20: Gina | G20: 100
B21: 08 | D21: =1+D20 -> 2759 | F21: Eloisa | G21: 100
B22: 08 | D22: =1+D21 -> 2760 | F22: Meldie Torres | G22: 100
B23: 08 | D23: =1+D22 -> 2761 | F23: Regine Estrada | G23: 100
B24: Sub-Total | G24: =SUM(G18:G23) -> 650 | I24: =G24-J24 -> 100 | J24: 550 | K24: 450 | L24: =J24+K24 -> 1000
B25: 15 | D25: 2762 | F25: cancelled | G25: 0
B26: 15 | D26: =1+D25 -> 2763 | F26: Lucy Saramosing | G26: 100
B27: 15 | D27: =1+D26 -> 2764 | F27: Jane Pasamba | G27: 100
B28: 15 | D28: =1+D27 -> 2765 | F28: Eloisa | G28: 100
B29: Sub-Total | G29: =SUM(G25:G28) -> 300 | I29: =G29-J29 -> -100 | J29: 400 | K29: 600 | L29: =J29+K29 -> 1000
B30: 22 | D30: 2766 | F30: Regide Meneses | G30: 100
B31: 22 | D31: =1+D30 -> 2767 | F31: Nida Angels | G31: 100
B32: 22 | D32: =1+D31 -> 2768 | F32: Gina Albarido | G32: 200
B33: 22 | D33: =1+D32 -> 2769 | F33: Annie Alejandia | G33: 50
B34: 22 | D34: =1+D33 -> 2770 | F34: Lucy Saramosing | G34: 100
B35: 22 | D35: =1+D34 -> 2771 | F35: Meldy Torres | G35: 100
B36: 22 | D36: =1+D35 -> 2772 | F36: Irene Masong | G36: 100
B37: 22 | D37: =1+D36 -> 2773 | F37: Elmer Buere | G37: 100
B38: 22 | D38: =1+D37 -> 2774 | F38: Susan Chua Uy | G38: 100
B39: 22 | D39: =1+D38 -> 2775 | F39: Helen C. & J. Pasamba | G39: =500+500 -> 1000
B40: Sub-Total | G40: =SUM(G30:G39) -> 1950 | I40: =G40-J40 -> 950 | J40: 1000 | K40: 0 | L40: =J40+K40 -> 1000
B41: TOTAL | G41: =G17+G24+G29+G40 -> 3200 | I41: =I17+I29+I24+I40 -> 950 | J41: =J17+J24+J29+J40 -> 2250 | K41: =K17+K24+K29+K40 -> 1750 | L41: =L17+L24+L29+L40 -> 4000
B50: Stipend for the month of September 2024
B52: Period covered | F52: Amount
B53: September | C53: 01 | F53: 1000
B54: September | C54: 08 | F54: 1000
B55: September | C55: 15 | F55: 1000
...

Sheet Oct-2024-FR
C4: Our Lady of the Most Holy Rosary (Sub-Parish)
C5: Diamond Crest Village ,Brgy, San Manuel, San Jose DelMonte City, Bulacan
C7: FINANCIAL REPORT
C8: As of October 31, 2024
C10: Cash Balance as of October 01, 2024 | L10: P | M10: -1459.83
C12: Add: Receipts for the month of October 2024
C14: Mass Collections: | G14: (Net of Stipend)
H16: Collections | I16: Stipend | J16: Others | K16: Net Amount
E18: October | G18: 06 | H18: 1400 | I18: 300 | J18: 0 | K18: =H18-I18-J18 -> 1100
E19: October | G19: 13 | H19: 1331 | I19: 600 | J19: 0 | K19: =H19-I19 -> 731
E20: October | G20: 17 | H20: 310 | I20: 0 | J20: 0 | K20: =H20-I20 -> 310
E21: October | G21: 18 | H21: 584 | I21: 0 | J21: 0 | K21: =H21-I21 -> 584
E22: October | G22: 19 | H22: 680 | I22: 0 | J22: 0 | K22: =H22-I22 -> 680
E23: October | G23: 20 | H23: 3382 | I23: 0 | J23: 0 | K23: =H23-I23 -> 3382
E24: October | G24: 27 | H24: 0 | I24: 0 | J24: 0 | K24: =H24-I24 -> 0 | P24: No mass
E26: Total | H26: =SUM(H18:H24) -> 7687 | I26: =SUM(I18:I24) -> 900 | J26: =SUM(J18:J24) -> 0 | K26: =SUM(K18:K24) -> 6787 | P26: =H26-I26 -> 6787
C30: Donations from Mass Intentions /Fiesta Collections/Pledges: (see Schedule A)
E32: Donations ( net of Stipend ) including Collections/donations from Fiesta Pledges | K32: ='Oct-2024-Sched A'!I55 -> 39750 | M32: =K32+K26 -> 46537
C34: Add: Cash withdrawal
E35: 39356 | K35: 20000
E36: 43009 | K36: 10000 | M36: =SUM(K35:K36) -> 30000
C38: Total Cash Available | L38: P | M38: =M32+M36+M10 -> 75077.17
C43: Less: Expenses for the month of October 2024
C45: Date | E45: PCV # | G45: Particulars | K45: Amount
C47: October 6 | G47: Banderitas | K47: 500
C48: October 6 | G48: Flowers Share at SLR Parish | K48: 1000 | P48: =K48+SUM(K50:K54) -> 5888.3 | Q48: 5288.3 | R48: =P48-Q48 -> 600
C49: October 7 | G49: Repair of ceiling (kitchen) | K49: 8900
C50: October 9 | G50: Dry Clean ( Santo Clothes ) | K50: 400
C51: October 10 | G51: Labor expenses ( for Banderitas ) | K51: 550
C52: October 11 | G52: Gift and Food Share ( Father Von's birthday ) | K52: 3000
C53: October 22 | G53: Electricity Expenses ( Meralco Bill - August 211 to September 20 ) | K53: 638.3
C54: October 22 | G54: Water Expenses ( Billing period - August 12-September 11 ) | K54: 300 | P54: =SUM(K47:K54) -> 15288.3 | Q54: 5288.3 | R54: =Q54-P54 -> -10000
C55: October 31 | G55: Fiesta Expenses (attached sched ) | K55: 47093.4 | M55: =SUM(K47:K55) -> 62381.7
C56: June 18, 2024 | G56: Utility Expenses ( Water Bills share for 2 months ) | K56: 0
C57: June 20, 2024 | G57: Battery for Laptop used at Chapel | K57: 0
C58: June 29, 2024 | G58: Candles | K58: 0
C59: June 30, 2024 | G59: Flowers at SLR Parish for the month of June 2024 | K59: 0 | M59: =SUM(K53:K59) -> 48031.7
C61: Net of Expenses | M61: =M38-M55 -> 12695.47 | P61: 11506.6 | Q61: 11506.6
P62: =2750+38.87 -> 2788.87 | Q62: 38.87
C63: Less: Deposits for the month of October 2024 | M63: 0 | P63: =P62+P61 -> 14295.47 | Q63: 1150 | R63: =SUM(Q62:Q63) -> 1188.87
...

Sheet Oct-2024-Sched A
B2: Schedule A
B7: Our Lady of the Most Holy Rosary (Sub-Parish)
G8: Control File - Receipts
F9: For the month of October 2024
G11: DONATIONS (Mass Intentions:Thanksgiving, Souls, others) | H11: DONATIONS | I11: Net of Donations | J11: STIPEND from | L11: Total Stipend
B12: Date | D12: OR Number | F12: Donor | J12: Donations | K12: Mass Collections
B13: October
B14: 06 | D14: 2776 | F14: Beng Grafil | G14: 100
B15: 06 | D15: =1+D14 -> 2777 | F15: Jerry | G15: 100
B16: 06 | D16: =1+D15 -> 2778 | F16: Elmer Buere | G16: 100
B17: 06 | D17: =1+D16 -> 2779 | F17: Jane Pasamba | G17: 100
B18: 06 | D18: =1+D16 -> 2779 | F18: Eloisa | G18: 100
B19: 06 | F19: No Official Receipt | G19: 200
B20: Sub-Total | G20: =SUM(G14:G19) -> 700 | I20: =G20-J20 -> 0 | J20: 700 | K20: 300 | L20: =J20+K20 -> 1000
B21: 13 | D21: 2781 | F21: Elmer Buere | G21: 200
B22: 13 | D22: =1+D21 -> 2782 | F22: Gina | G22: 100
B23: 13 | D23: =1+D22 -> 2783 | F23: Eloisa | G23: 100
B24: 13 | D24: =1+D23 -> 2784 | F24: Madel Belino | G24: 1500 | M24: env # 13
B25: Sub-Total | G25: =SUM(G21:G24) -> 1900 | I25: =G25-J25 -> 1500 | J25: 400 | K25: 600 | L25: =J25+K25 -> 1000
B26: 18 | D26: 2785 | F26: Elmer Buere | G26: 100
B27: 18 | D27: =1+D26 -> 2786 | F27: Elmer Buere | G27: 100
B28: 18 | D28: =1+D27 -> 2787 | F28: Belma | G28: 400
B29: 18 | D29: =1+D28 -> 2788 | F29: Pres SaraNanette | G29: 500
B30: 18 | D30: =1+D29 -> 2789 | F30: Ebony | G30: 500 | M30: env #14
B31: 18 | D31: =1+D30 -> 2790 | F31: Edna Mejia | G31: 500 | M31: env #24
B32: 18 | D32: =1+D31 -> 2791 | F32: Aviles Family | G32: 500 | M32: env #21
B33: Sub-Total | G33: =SUM(G26:G32) -> 2600 | I33: =G33-J33 -> 1100 | J33: 1500 | K33: 0 | L33: =J33+K33 -> 1500
B34: 19 | D34: 2792 | F34: Regine Estrada | G34: 200
B35: 19 | D35: =1+D34 -> 2793 | F35: Elmer Buere | G35: 100
B36: Sub-Total | G36: =SUM(G34:G35) -> 300 | I36: =G36-J36 -> 300
B37: 20 | D37: 2794 | F37: Imelda Torres | G37: 100
B38: 20 | D38: =1+D37 -> 2795 | F38: Gary Mariano | G38: 100
B39: 20 | D39: =1+D38 -> 2796 | F39: Damian Family | G39: 100
B40: 20 | D40: =1+D39 -> 2797 | F40: Jane Pasamba | G40: 100
B41: 20 | D41: =1+D40 -> 2798 | F41: Basilia Family | G41: 50
B42: 20 | D42: =1+D41 -> 2799 | F42: blank | G42: 0
B43: 20 | D43: =1+D42 -> 2800 | F43: Rose Riambon | G43: 1500 | M43: env #7
B44: Sub-Total | G44: =SUM(G37:G43) -> 1950 | I44: =G44-J44 -> 450 | J44: 1500 | L44: =J44+K44 -> 1500
B45: 12 | D45: 2801 | F45: Art De Leon | G45: 5000
B46: 13 | D46: =1+D45 -> 2802 | F46: Nida Albato | G46: 4000
...

Sheet Oct - Fiesta-details
A2: FIESTA COLLECTION from Envelopes:
A3: Total as counted by Lucy, Gina & Lucky ……………
B4: Env. No. | D4: Amount | F4: Rcpt. # | H4: Stipend
A5: Luz Damian | B5: 01 | D5: 1000
A6: Merly Pagayon | B6: 04 | D6: 500
A7: Nanie Domingo | B7: 05 | D7: 200
A8: Rose Riambon | B8: 07 | C8: 1500 | D8: 1500 | F8: 2800 | H8: 1500 | I8: (10/19) | J8: =H8 -> 1500
A9: Emma Ortega | B9: 08 | D9: 100
A10: M. Tabuena | B10: 09 | C10: 1000 | D10: 1000 | F10: 2804
A11: Art de Leon | B11: 10 | C11: =D11 -> 5000 | D11: 5000 | F11: 2801
A12: Lara Fam. | B12: 11 | D12: 200
A13: Jane Pasamba | B13: 12 | D13: 500
A14: Madel Belino | B14: 13 | C14: =D14 -> 1500 | D14: 1500 | F14: 2784 | H14: 1500 | I14: (10/17) | J14: =H14 -> 1500
A15: Ebon Andres | B15: 14 | C15: =D15 -> 500 | D15: 500 | F15: 2789 | H15: 0
A16: Emily Silva | B16: 15 | D16: 1000
A17: Beng Grafil | B17: 17 | D17: 1000
A18: Baby Boris | B18: 20 | D18: 1000
A19: Leony Aviles | B19: 21 | C19: =D19 -> 500 | D19: 500 | F19: 2791 | H19: 500
A20: Eloisa Banog | B20: 22 | D20: 250
A21: Bautro Fam. | B21: 23 | D21: 200
A22: Edna Mejia | B22: 24 | C22: =D22 -> 500 | D22: 500 | F22: 2790 | H22: 0
A23: Masong Fam. | B23: 26 | C23: =D23 -> 1000 | D23: 1000 | F23: 2790
A24: Chua-Uy & Padua Fam. | B24: 29 | D24: 150
A25: Tess Sabado | B25: 31 | D25: 500
A26: Helen Caballero | B26: 32 | D26: 200
A27: Grace Conseja | B27: 33 | D27: 300
A28: Gina Singun | B28: 34 | D28: 500
A29: Ellen Mendoza | B29: 37 | D29: 500
A30: Lorena Bianzon | B30: 40 | D30: 3000
A31: Grace Villarisco | B31: 44 | C31: =D31 -> 5000 | D31: 5000 | F31: 2806
A32: Nanette Sara | B32: 46 | C32: =D32 -> 500 | D32: 500 | F32: 2788 | H32: 500 | I32: (10/18) | J32: =SUM(H19:H32) -> 1000
A33: Saringan Fam. | B33: 48 | C33: =D33 -> 1000 | D33: 1000 | F33: 2807
A34: Regine Estrada | B34: 49 | C34: =D34 -> 1000 | D34: 1000 | F34: 2787
A35: Tina Murla | D35: 2000
A36: Howie | D36: 500
D37: =SUM(D5:D36) -> 32600 | H37: =SUM(H5:H36) -> 4000
D38: =D37-H37 -> 28600
A39: No OR | C39: =SUM(C5:C34) -> 19000 | D39: =D36+D35+SUM(D24:D30)+D21+D20+D18+D17+D16+D13+D12+D9+D7+D6+D5 -> 13600
A40: With OR | D40: =C39 -> 19000
A41: Collections from Envelopes | D41: =D40+D39 -> 32600
...

Sheet Nov-2024-FR
C4: Our Lady of the Most Holy Rosary (Sub-Parish)
C5: Diamond Crest Village ,Brgy, San Manuel, San Jose DelMonte City, Bulacan
C7: FINANCIAL REPORT
C8: As of November 30, 2024
C10: Cash Balance as of November 01, 2024 | L10: P | M10: ='Oct-2024-FR'!M65 -> 12695.47 | O10: 11506.6 | P10: =O10-M10 -> -1188.87
C12: Add: Receipts for the month of November 2024
C14: Mass Collections: | G14: (Net of Stipend)
H16: Collections | I16: Stipend | J16: Others | K16: Net Amount
E18: November | G18: 03 | H18: 603 | I18: 0 | J18: 0 | K18: =H18-I18-J18 -> 603
E19: November | G19: 10 | H19: 1609 | I19: 450 | J19: 0 | K19: =H19-I19 -> 1159
E20: November | G20: 17 | H20: 833 | I20: 400 | J20: 0 | K20: =H20-I20 -> 433
E21: October | G21: 18 | H21: 0 | I21: 0 | J21: 0 | K21: =H21-I21 -> 0
E22: October | G22: 19 | H22: 0 | I22: 0 | J22: 0 | K22: =H22-I22 -> 0
E23: October | G23: 20 | H23: 0 | I23: 0 | J23: 0 | K23: =H23-I23 -> 0
E24: October | G24: 27 | H24: 0 | I24: 0 | J24: 0 | K24: =H24-I24 -> 0 | O24: No mass
E26: Total | H26: =SUM(H18:H24) -> 3045 | I26: =SUM(I18:I24) -> 850 | J26: =SUM(J18:J24) -> 0 | K26: =SUM(K18:K24) -> 2195 | O26: =H26-I26 -> 2195
C30: Donations from Mass Intentions (see Schedule A)
E32: Donations ( net of Stipend ) | K32: ='Nov-2024-Sched A'!I55 -> 1000 | M32: =K32+K26 -> 3195
C34: Add: Cash withdrawal
E35: 39356 | K35: 0
E36: 43009 | K36: 0 | M36: =SUM(K35:K36) -> 0
C38: Total Cash Available | L38: P | M38: =M32+M36+M10 -> 15890.47
C43: Less: Expenses for the month of November 2024
C45: Date | E45: PCV # | G45: Particulars | K45: Amount
C47: November 3 | G47: Parol ( partial payment ) | K47: 1000
C48: November 16 | G48: Financial Assistance to DLC IV (Feast of Christ the King) | K48: 1000
C49: November 17 | G49: Stipend - DCV mass sponsor on Novenario Masses | K49: 500
C50: November 26 | G50: Purchase of christmas lights ( chapel décor ) | K50: 693.1
C51: November 29 | G51: Labor expenses ( Bioman 's assistance in the decoration and cleaning of the chapel | K51: 471.5
C52: November 29 | G52: Candles | K52: 141.5 | M52: =SUM(K47:K52) -> 3806.1
C53: November 29 | G53: Electricity Expenses ( Meralco Bill - August 211 to September 20 ) | K53: 0
C54: November 29 | G54: Water Expenses ( Billing period - August 12-September 11 ) | K54: 0
C55: November 29 | K55: 0 | M55: 0
C56: June 18, 2024 | G56: Utility Expenses ( Water Bills share for 2 months ) | K56: 0
C57: June 20, 2024 | G57: Battery for Laptop used at Chapel | K57: 0
C58: June 29, 2024 | G58: Candles | K58: 0
C59: June 30, 2024 | G59: Flowers at SLR Parish for the month of June 2024 | K59: 0 | M59: =SUM(K53:K59) -> 0
C61: Net of Expenses | M61: =M38-M52 -> 12084.37
C63: Less: Deposits for the month of November 2024 | M63: 11506.6
C65: Cash Balance as of November 30, 2024 | L65: P | M65: =M61-M63 -> 577.77
...

Sheet Nov-2024-Sched A
B2: Schedule A
B7: Our Lady of the Most Holy Rosary (Sub-Parish)
G8: Control File - Receipts
F9: For the month of November 2024
G11: DONATIONS (Mass Intentions:Thanksgiving, Souls, others) | H11: DONATIONS | I11: Net of Donations | J11: STIPEND from | L11: Total Stipend
B12: Date | D12: OR Number | F12: Donor | J12: Donations | K12: Mass Collections
B13: November
B14: 03 | D14: 2808 | F14: Art De Leon | G14: 500
B15: 03 | D15: =1+D14 -> 2809 | F15: Elmer Buere | G15: 100
B16: 03 | D16: =1+D15 -> 2810 | F16: Beng Grafil | G16: 100
B17: 03 | D17: =1+D16 -> 2811 | F17: Banog Family | G17: 100
B18: 03 | D18: =1+D17 -> 2812 | F18: Ebony | G18: 100
B19: 03 | D19: =1+D18 -> 2813 | F19: Grafil Family | G19: 1000 | M19: env # 17
B20: Sub-Total | G20: =SUM(G14:G19) -> 1900 | I20: =G20-J20 -> 900 | J20: 1000 | K20: 0 | L20: =J20+K20 -> 1000
B21: 10 | D21: 2814 | F21: Lucy | G21: 100
B22: 10 | D22: =1+D21 -> 2815 | F22: Lucy | G22: 50
B23: 10 | D23: =1+D22 -> 2816 | F23: Gina | G23: 100
B24: 10 | D24: =1+D23 -> 2817 | F24: Imelda | G24: 100
B25: 10 | D25: =1+D24 -> 2818 | F25: Juvy | G25: 100
B26: 10 | D26: =1+D25 -> 2819 | F26: Eloisa | G26: 100
B27: Sub-Total | G27: =SUM(G21:G26) -> 550 | I27: =G27-J27 -> 0 | J27: 550 | K27: 450 | L27: =J27+K27 -> 1000
B28: 17 | D28: 2820 | F28: Gina | G28: 100
B29: 17 | D29: =1+D28 -> 2821 | F29: Art De Leon | G29: 200
B30: 17 | D30: =1+D29 -> 2822 | F30: Jane Pasamba | G30: 100
B31: 17 | D31: =1+D30 -> 2823 | F31: Jonie | G31: 100
B32: 17 | D32: =1+D31 -> 2824 | F32: Beng Grafil | G32: 100
B33: 17 | D33: =1+D32 -> 2825 | F33: Elmer Buere | G33: 100
B34: Sub-Total | G34: =SUM(G28:G33) -> 700 | I34: =G34-J34 -> 100 | J34: 600 | K34: 400 | L34: =J34+K34 -> 1000
B35: 19 | D35: 2792 | F35: Regine Estrada
B36: 19 | D36: =1+D35 -> 2793 | F36: Elmer Buere
B37: Sub-Total | G37: =SUM(G35:G36) -> 0 | I37: =G37-J37 -> 0
B38: 20 | D38: 2794 | F38: Imelda Torres
B39: 20 | D39: =1+D38 -> 2795 | F39: Gary Mariano
B40: 20 | D40: =1+D39 -> 2796 | F40: Damian Family
B41: 20 | D41: =1+D40 -> 2797 | F41: Jane Pasamba
B42: 20 | D42: =1+D41 -> 2798 | F42: Basilia Family
B43: 20 | D43: =1+D42 -> 2799 | F43: blank | G43: 0
B44: 20 | D44: =1+D43 -> 2800 | F44: Rose Riambon
B45: Sub-Total | G45: =SUM(G38:G44) -> 0 | I45: =G45-J45 -> 0 | J45: 0 | L45: =J45+K45 -> 0
B46: 12 | D46: 2801 | F46: Art De Leon
...

Sheet Dec-2024-FR
C4: Our Lady of the Most Holy Rosary (Sub-Parish)
C5: Diamond Crest Village ,Brgy, San Manuel, San Jose DelMonte City, Bulacan
C7: FINANCIAL REPORT
C8: As of December 31, 2024
C12: Cash Balance as of December 01, 2024 | L12: P | M12: 577.77
C14: Add: Receipts for the month of December 2024
C16: Mass Collections: | G16: (Net of Stipend)
H18: Collections | I18: Stipend | J18: Others | K18: Net Amount
E20: December | G20: 01 | H20: 2139 | I20: 300 | J20: 0 | K20: =H20-I20-J20 -> 1839
E21: December | G21: 08 | H21: 2021 | I21: 300 | J21: 0 | K21: =H21-I21-J21 -> 1721
E22: December | G22: 15 | H22: 3157 | J22: 0 | K22: =H22-I22-J22 -> 3157
E23: December | G23: =1+G22 -> 16 | H23: 1513 | J23: 0 | K23: =H23-I23-J23 -> 1513
E24: December | G24: =1+G23 -> 17 | H24: 1731 | J24: 0 | K24: =H24-I24-J24 -> 1731
E25: December | G25: =1+G24 -> 18 | H25: 1063 | I25: 500 | J25: 0 | K25: =H25-I25-J25 -> 563
E26: December | G26: =1+G25 -> 19 | H26: 1759 | J26: 0 | K26: =H26-I26-J26 -> 1759
E27: December | G27: =1+G26 -> 20 | H27: 1774 | J27: 0 | K27: =H27-I27-J27 -> 1774
E28: December | G28: =1+G27 -> 21 | H28: 1447 | J28: 0 | K28: =H28-I28-J28 -> 1447
E29: December | G29: =1+G28 -> 22 | H29: 3316 | J29: 0 | K29: =H29-I29-J29 -> 3316
E30: December | G30: =1+G29 -> 23 | H30: 1806 | J30: 0 | K30: =H30-I30-J30 -> 1806
E31: December | G31: 25 | H31: 1631 | J31: 0 | K31: =H31-I31-J31 -> 1631
E32: December | G32: 29 | H32: 1104 | I32: 600 | J32: 0 | K32: =H32-I32-J32 -> 504
E33: October | G33: 18 | H33: 0 | I33: 0 | J33: 0 | K33: =H33-I33 -> 0
E34: October | G34: 19 | H34: 0 | I34: 0 | J34: 0 | K34: =H34-I34 -> 0
E35: October | G35: 20 | H35: 0 | I35: 0 | J35: 0 | K35: =H35-I35 -> 0
E36: October | G36: 27 | H36: 0 | I36: 0 | J36: 0 | K36: =H36-I36 -> 0 | O36: No mass
E38: Total | H38: =SUM(H20:H36) -> 24461 | I38: =SUM(I20:I36) -> 1700 | J38: =SUM(J20:J36) -> 0 | K38: =SUM(K20:K36) -> 22761 | O38: =H38-I38 -> 22761
C42: Donations from Mass Intentions /Pledges: (see Schedule A)
E44: Donations ( net of Stipend ) | K44: ='Dec-2024-Sched A'!I102 -> 4450 | M44: =K44+K38 -> 27211
C46: Add: Cash withdrawal | M46: 5500
E47: 39356 | K47: 0
E48: 43009 | K48: 0 | M48: =SUM(K47:K48) -> 0
C50: Total Cash Available | L50: P | M50: =M46+M44+M12 -> 33288.77
C55: Less: Expenses for the month of December 2024
C57: Date | E57: PCV # | G57: Particulars | K57: Amount
C59: December 1 | G59: Ordo | K59: 300
C60: December 1 | G60: Gel Candles | K60: 690
C61: December 1 | G61: Parol (last payment) | K61: 1000
C62: December 3 | G62: SPPC share ( Angels-SLR Parish ) | K62: 3000
C63: December 4 | G63: Repair of 2 outlets (Chapel) | K63: 260
C64: December 6 | G64: Installation of christmas decors | K64: 768.6
...

Sheet Dec-2024-Sched A
B2: Schedule A
B5: Our Lady of the Most Holy Rosary (Sub-Parish)
G6: Control File - Receipts
F7: For the month of December 2024
G9: DONATIONS (Mass Intentions:Thanksgiving, Souls, others) | H9: DONATIONS | I9: Net of Donations | J9: STIPEND from | L9: Total Stipend
B10: Date | D10: OR Number | F10: Donor | J10: Donations | K10: Mass Collections
B11: December
B12: 01 | D12: 2826 | F12: Beng Grafil & Family | G12: 100
B13: 01 | D13: =1+D12 -> 2827 | F13: Jane Pasamba & Family | G13: 100
B14: 01 | D14: =1+D13 -> 2828 | F14: Lucy & Family | G14: 100
B15: 01 | D15: =1+D14 -> 2829 | F15: Elmer Buere | G15: 100
B16: 01 | D16: =1+D15 -> 2830 | F16: Irene Masong | G16: 100
B17: 01 | D17: =1+D16 -> 2831 | F17: Lucy Salas | G17: 100
B18: 01 | D18: =1+D17 -> 2832 | F18: Juvy Mateo | G18: 100
B19: Sub-Total | G19: =SUM(G12:G18) -> 700 | I19: =G19-J19 -> 0 | J19: 700 | K19: 300 | L19: =J19+K19 -> 1000
B20: 08 | D20: 2833 | F20: Beng Grafil & Family | G20: 100
B21: 08 | D21: =1+D20 -> 2834 | F21: Eloisa | G21: 100
B22: 08 | D22: =1+D21 -> 2835 | F22: Ebony | G22: 100
B23: 08 | D23: =1+D22 -> 2836 | F23: Susan Chua | G23: 100
B24: 08 | D24: =1+D22 -> 2836 | F24: Susan Chua | G24: 100
F25: No Official Receipt | G25: 0
B26: Sub-Total | G26: =SUM(G20:G25) -> 500 | I26: =G26-J26 -> -200 | J26: 700 | K26: 300 | L26: =J26+K26 -> 1000
B27: 15 | D27: 2838 | F27: Art De Leon | G27: 200 | L27: =J27+K27 -> 0
B28: 15 | D28: =1+D27 -> 2839 | F28: Freddie Damian | G28: 100 | L28: =J28+K28 -> 0
B29: 15 | D29: =1+D28 -> 2840 | F29: Lucy | G29: 100 | L29: =J29+K29 -> 0
B30: 15 | D30: =1+D29 -> 2841 | F30: Gina | G30: 100 | L30: =J30+K30 -> 0
B31: 15 | D31: =1+D30 -> 2842 | F31: Beng Grafil & Family | G31: 1500 | J31: 0 | L31: =J31+K31 -> 0 | M31: stipend-Dec 15 | P31: 1500
B32: 15 | D32: =1+D31 -> 2843 | F32: Fely Rabano | G32: 1500 | J32: 0 | L32: =J32+K32 -> 0 | M32: stipend-Dec 16 | P32: 1500
B33: 15 | D33: =1+D32 -> 2844 | F33: Terrie Pisalbon | G33: 3000 | L33: =J33+K33 -> 0 | M33: stipend-Dec 16
B34: 15 | D34: =1+D33 -> 2845 | F34: Belma | G34: 600 | J34: 0 | L34: =J34+K34 -> 0
B35: Sub-Total | G35: =SUM(G27:G34) -> 7100 | I35: =G35-J31-J32-J35 -> 2600 | J35: 4500 | L35: =J35+K35 -> 4500 | M35: stipend-Dec 15, 16 &17
B36: 16 | D36: 2846 | F36: Molina Family | G36: 200 | L36: =J36+K36 -> 0
B37: Sub-Total | G37: =G36 -> 200 | I37: =G37-J33-J34-J37 -> 200 | L37: =J37+K37 -> 0
B38: 17 | D38: 2847 | F38: Molina Family | G38: 100 | L38: =J38+K38 -> 0
B39: 17 | D39: 2848 | F39: Elmer Buere | G39: 100 | L39: =J39+K39 -> 0
B40: 17 | D40: 2849 | F40: Leaticia | G40: 200 | L40: =J40+K40 -> 0
B41: Sub-Total | G41: =SUM(G38:G40) -> 400 | I41: =G41-J37-J38-J41 -> 400 | L41: =J41+K41 -> 0
